2022-02-07 15:09:35 WARNING (SyncWorker_0) [homeassistant.loader] We found a custom integration hacs which has not been tested by Home Assistant. This component might cause stability problems, be sure to disable it if you experience issues with Home Assistant
2022-02-07 15:09:35 WARNING (SyncWorker_0) [homeassistant.loader] We found a custom integration apple_tv which has not been tested by Home Assistant. This component might cause stability problems, be sure to disable it if you experience issues with Home Assistant
2022-02-07 15:09:35 WARNING (SyncWorker_1) [homeassistant.loader] We found a custom integration alexa_media which has not been tested by Home Assistant. This component might cause stability problems, be sure to disable it if you experience issues with Home Assistant
2022-02-07 15:09:35 WARNING (SyncWorker_0) [homeassistant.loader] We found a custom integration pirateweather which has not been tested by Home Assistant. This component might cause stability problems, be sure to disable it if you experience issues with Home Assistant
2022-02-07 15:09:35 WARNING (SyncWorker_1) [homeassistant.loader] We found a custom integration eventsensor which has not been tested by Home Assistant. This component might cause stability problems, be sure to disable it if you experience issues with Home Assistant
2022-02-07 15:10:52 ERROR (Thread-4) [xiaomi_gateway] Unknown gateway ip 192.168.10.121
2022-02-07 15:10:53 ERROR (MainThread) [homeassistant.components.unifi] Error connecting to the UniFi Network at 192.168.10.155: Call https://192.168.10.155:8443 received 404 Not Found
2022-02-07 15:11:12 INFO (MainThread) [pyhap.accessory_driver] Starting accessory Home Assistant Bridge on address 192.168.10.155, port 21063.
2022-02-07 15:11:12 INFO (MainThread) [pyhap.hap_protocol] ('192.168.10.162', 51019): Connection made to Home Assistant Bridge
2022-02-07 15:11:14 INFO (MainThread) [pyhap.hap_protocol] ('192.168.10.51', 49163): Connection made to Home Assistant Bridge
2022-02-07 15:11:14 INFO (MainThread) [pyhap.hap_protocol] ('192.168.10.40', 50101): Connection made to Home Assistant Bridge
2022-02-07 15:11:14 INFO (MainThread) [pyhap.hap_protocol] ('192.168.10.48', 62340): Connection made to Home Assistant Bridge
2022-02-07 15:11:14 INFO (MainThread) [pyhap.hap_protocol] ('192.168.10.135', 55494): Connection made to Home Assistant Bridge
2022-02-07 15:11:14 INFO (MainThread) [pyhap.hap_protocol] ('192.168.10.56', 50143): Connection made to Home Assistant Bridge
2022-02-07 15:22:56 ERROR (MainThread) [homeassistant.components.tplink.coordinator] Error fetching 192.168.11.112 data: Unable to connect to the device: 192.168.11.112
2022-02-07 15:38:15 ERROR (SyncWorker_2) [homeassistant.helpers.location] Unable to find entity Home
2022-02-07 16:53:06 ERROR (SyncWorker_6) [xiaomi_gateway] Cannot connect to Gateway
2022-02-07 16:53:06 ERROR (SyncWorker_6) [xiaomi_gateway] No data in response from hub None
2022-02-07 16:57:49 ERROR (MainThread) [homeassistant.components.websocket_api.http.connection] [140342808738496] Error handling message: Unknown error
Traceback (most recent call last):
  File "/usr/src/homeassistant/homeassistant/components/websocket_api/connection.py", line 107, in async_handle
    handler(self.hass, self, schema(msg))
  File "/usr/src/homeassistant/homeassistant/components/search/__init__.py", line 54, in websocket_search_related
    msg["id"], searcher.async_search(msg["item_type"], msg["item_id"])
  File "/usr/src/homeassistant/homeassistant/components/search/__init__.py", line 96, in async_search
    getattr(self, f"_resolve_{search_type}")(search_id)
  File "/usr/src/homeassistant/homeassistant/components/search/__init__.py", line 163, in _resolve_device
    for entity_id in script.scripts_with_device(self.hass, device_id):
  File "/usr/src/homeassistant/homeassistant/components/script/__init__.py", line 114, in scripts_with_device
    return [
  File "/usr/src/homeassistant/homeassistant/components/script/__init__.py", line 117, in <listcomp>
    if device_id in script_entity.script.referenced_devices
  File "/usr/src/homeassistant/homeassistant/helpers/script.py", line 1105, in referenced_devices
    Script._find_referenced_devices(self._referenced_devices, self.sequence)
  File "/usr/src/homeassistant/homeassistant/helpers/script.py", line 1119, in _find_referenced_devices
    _referenced_extract_ids(data, ATTR_DEVICE_ID, referenced)
  File "/usr/src/homeassistant/homeassistant/helpers/script.py", line 926, in _referenced_extract_ids
    item_ids = data.get(key)
AttributeError: 'Template' object has no attribute 'get'
2022-02-07 17:00:15 ERROR (MainThread) [homeassistant.components.websocket_api.http.connection] [140342808738496] Error handling message: Unknown error
Traceback (most recent call last):
  File "/usr/src/homeassistant/homeassistant/components/websocket_api/connection.py", line 107, in async_handle
    handler(self.hass, self, schema(msg))
  File "/usr/src/homeassistant/homeassistant/components/search/__init__.py", line 54, in websocket_search_related
    msg["id"], searcher.async_search(msg["item_type"], msg["item_id"])
  File "/usr/src/homeassistant/homeassistant/components/search/__init__.py", line 96, in async_search
    getattr(self, f"_resolve_{search_type}")(search_id)
  File "/usr/src/homeassistant/homeassistant/components/search/__init__.py", line 163, in _resolve_device
    for entity_id in script.scripts_with_device(self.hass, device_id):
  File "/usr/src/homeassistant/homeassistant/components/script/__init__.py", line 114, in scripts_with_device
    return [
  File "/usr/src/homeassistant/homeassistant/components/script/__init__.py", line 117, in <listcomp>
    if device_id in script_entity.script.referenced_devices
  File "/usr/src/homeassistant/homeassistant/helpers/script.py", line 1105, in referenced_devices
    Script._find_referenced_devices(self._referenced_devices, self.sequence)
  File "/usr/src/homeassistant/homeassistant/helpers/script.py", line 1119, in _find_referenced_devices
    _referenced_extract_ids(data, ATTR_DEVICE_ID, referenced)
  File "/usr/src/homeassistant/homeassistant/helpers/script.py", line 926, in _referenced_extract_ids
    item_ids = data.get(key)
AttributeError: 'Template' object has no attribute 'get'
2022-02-07 17:01:42 INFO (MainThread) [pyhap.accessory_driver] Stopping accessory Home Assistant Bridge on address 192.168.10.155, port 21063.
2022-02-07 17:01:43 ERROR (Thread-4) [root] Uncaught thread exception
Traceback (most recent call last):
  File "/usr/local/lib/python3.9/threading.py", line 973, in _bootstrap_inner
    self.run()
  File "/usr/local/lib/python3.9/threading.py", line 910, in run
    self._target(*self._args, **self._kwargs)
  File "/usr/local/lib/python3.9/site-packages/xiaomi_gateway/__init__.py", line 180, in _listen_to_msg
    data, (ip_add, _) = self._mcastsocket.recvfrom(SOCKET_BUFSIZE)
OSError: [Errno 9] Bad file descriptor
